Workbook

Sheet Ratio Calculations Microsoft
A1: Company | B1: Type of Ratio | C1: Name | D1: Formula | E1: Result for 2025 | F1: Result for 2024
A2: MICROSOFT | B2: Liquidy | C2: Current Ratio | D2: Current Assets / Current Liablities | E2: ='Financial Data Microsoft'!C3/'Financial Data Microsoft'!C4 -> 1.3534464 | F2: ='Financial Data Microsoft'!D3/'Financial Data Microsoft'!D4 -> 1.2749549
A3: MICROSOFT | B3: Liquidy | C3: Quick Acidity Ratio | D3: (Current Assets - Inventory) / Current Liabilities | E3: =('Financial Data Microsoft'!C3 - 'Financial Data Microsoft'!C21)/'Financial Data Microsoft'!C7 -> 1.3468042 | F3: =('Financial Data Microsoft'!D3 - 'Financial Data Microsoft'!D21)/'Financial Data Microsoft'!D7 -> 1.2650097
A4: MICROSOFT | B4: Liquidy | C4: Average Collection Period | D4: 365 * Accounts Receivable / Annual Credit Sales | E4: =365*'Financial Data Microsoft'!C22/'Financial Data Microsoft'!C11 -> 90.568517 | F4: =365*'Financial Data Microsoft'!D22/'Financial Data Microsoft'!D11 -> 84.762934
A5: MICROSOFT | B5: Liquidy | C5: Accounts Receivable Turnover | D5: Annual Credit Sales / Accounts Receivable | E5: ='Financial Data Microsoft'!C12/'Financial Data Microsoft'!C22 -> 4.030098 | F5: ='Financial Data Microsoft'!D12/'Financial Data Microsoft'!D22 -> 4.3061275
A6: MICROSOFT | B6: Liquidy | C6: Inventory Turnover | D6: Costs of Goods Sold / Inventory | E6: ='Financial Data Microsoft'!C15/'Financial Data Microsoft'!C21 -> 93.636461 | F6: ='Financial Data Microsoft'!D15/'Financial Data Microsoft'!D21 -> 59.505618
A7: MICROSOFT | B7: Capital Structure | C7: Debt Ratio | D7: Total Debt / Total Assets | E7: ='Financial Data Microsoft'!C8/'Financial Data Microsoft'!C5 -> 0.44510931 | F7: ='Financial Data Microsoft'!D8/'Financial Data Microsoft'!D5 -> 0.47579774
A8: MICROSOFT | B8: Capital Structure | C8: Times Interest Earned | D8: Net Operational Income / Interest Expense | E8: ='Financial Data Microsoft'!C18/'Financial Data Microsoft'!C19 -> 53.001237 | F8: ='Financial Data Microsoft'!D18/'Financial Data Microsoft'!D19 -> 36.685551
A9: MICROSOFT | B9: Asset Management Efficiency Ratios | C9: Total Asset Turnover | D9: Sales / Total Assets | E9: ='Financial Data Microsoft'!C12/'Financial Data Microsoft'!C5 -> 0.45512542 | F9: ='Financial Data Microsoft'!D12/'Financial Data Microsoft'!D5 -> 0.47860154
A10: MICROSOFT | B10: Asset Management Efficiency Ratios | C10: Fixed Asset Turnover | D10: Sales / Net Plant and Equipment | E10: ='Financial Data Microsoft'!C12/'Financial Data Microsoft'!C14 -> 1.3744914 | F10: ='Financial Data Microsoft'!D12/'Financial Data Microsoft'!D14 -> 1.8077777
A11: MICROSOFT | B11: Profitability Ratios | C11: Gross Profit Margin | D11: Gross Profits / Sales | E11: ='Financial Data Microsoft'!C16/'Financial Data Microsoft'!C12 -> 0.68823742 | F11: ='Financial Data Microsoft'!D16/'Financial Data Microsoft'!D12 -> 0.69764444
A12: MICROSOFT | B12: Profitability Ratios | C12: Net Profit Margin | D12: Net Income / Sales | E12: ='Financial Data Microsoft'!C20/'Financial Data Microsoft'!C12 -> 0.36146015 | F12: ='Financial Data Microsoft'!D20/'Financial Data Microsoft'!D12 -> 0.35955973
A13: MICROSOFT | B13: Profitability Ratios | C13: Operating Profit Margin | D13: Net Operating Income / Sales | E13: ='Financial Data Microsoft'!C18/'Financial Data Microsoft'!C12 -> 0.45621956 | F13: ='Financial Data Microsoft'!D18/'Financial Data Microsoft'!D12 -> 0.446443
A14: MICROSOFT | B14: Profitability Ratios | C14: Operating Return on Assets | D14: Net Operating Income / Total Assets | E14: ='Financial Data Microsoft'!C18/'Financial Data Microsoft'!C5 -> 0.20763712 | F14: ='Financial Data Microsoft'!D18/'Financial Data Microsoft'!D5 -> 0.2136683
A15: MICROSOFT | B15: Profitability Ratios | C15: Return on Equity | D15: Net Income / Common Equity | E15: ='Financial Data Microsoft'!C20/'Financial Data Microsoft'!C9 -> 0.933425 | F15: ='Financial Data Microsoft'!D20/'Financial Data Microsoft'!D9 -> 0.87329945
A16: MICROSOFT | B16: Market Value Ratios | C16: Price Earning Ratio | D16: Market Price per Share / Earnings per Share | E16: ='Financial Data Microsoft'!C28/'Financial Data Microsoft'!C30 -> 37.627566 | F16: ='Financial Data Microsoft'!D28/'Financial Data Microsoft'!D30 -> 35.840678
A17: MICROSOFT | B17: Market Value Ratios | C17: Market-to Book Ratio | D17: Market Price per Share / Book Value per Share | E17: ='Financial Data Microsoft'!C28/'Financial Data Microsoft'!C34 -> 11.157391 | F17: ='Financial Data Microsoft'!D28/'Financial Data Microsoft'!D34 -> 11.76739
A18: MICROSOFT | B18: DuPont Analysis | C18: Return on Equity (DuPont) | D18: Net Profit Margin * Total Asset Turnover * Equity Multiplier | E18: =E12*E9*E19 -> 0.933425 | F18: =F12*F9*F19 -> 0.87329945
A19: MICROSOFT | B19: DuPont Analysis | C19: Equity Multiplier | D19: Total Assets / Common Equity | E19: ='Financial Data Microsoft'!C5/'Financial Data Microsoft'!C9 -> 5.6739814 | F19: ='Financial Data Microsoft'!D5/'Financial Data Microsoft'!D9 -> 5.0747897

Sheet Ratio Calculations Oracle
A1: Company | B1: Type of Ratio | C1: Name | D1: Formula | E1: Result for 2025 | F1: Result for 2024 | G1: remarks
A2: ORACLE | B2: Liquidy | C2: Current Ratio | D2: Current Assets / Current Liablities | E2: ='Financial Data Oracle'!C3/'Financial Data Oracle'!C4 -> 0.75502242 | F2: ='Financial Data Oracle'!D3/'Financial Data Oracle'!D4 -> 0.71477467
A3: ORACLE | B3: Liquidy | C3: Quick Ratio (Acidity-Test) | D3: (Current Assets - Inventory) / Current Liabilities | E3: =('Financial Data Oracle'!C3 - 'Financial Data Oracle'!C21) / 'Financial Data Oracle'!C7 -> 0.74368165 | F3: =('Financial Data Oracle'!D3 - 'Financial Data Oracle'!D21) / 'Financial Data Oracle'!D7 -> 0.70441288
A4: ORACLE | B4: Liquidity | C4: Average Collection Period | D4: 365 * Accounts Receivable / Annual Credit Sales | E4: =365*'Financial Data Oracle'!C22/'Financial Data Oracle'!C12 -> 54.420286 | F4: =365*'Financial Data Oracle'!D22/'Financial Data Oracle'!D12 -> 54.266536 | G4: couldn't find annual credit sales; based on research, the total sales in most sources is used as total annual credit sales; till futher research, sales/revenue is used for the calculation
A5: ORACLE | B5: Liquidity | C5: Accounts Receivable Turnover | D5: Annual Credit Sales / Accounts Receivable | E5: ='Financial Data Oracle'!C11/'Financial Data Oracle'!C22 -> 5.7516943 | F5: ='Financial Data Oracle'!D11/'Financial Data Oracle'!D22 -> 5.6809754 | G5: couldn't find annual credit sales; based on research, the total sales in most sources is used as total annual credit sales; till futher research, sales/revenue is used for the calculation
A6: ORACLE | B6: Liquidity | C6: Inventory Turnover | D6: Costs of Goods Sold / Inventory | E6: ='Financial Data Oracle'!C15/'Financial Data Oracle'!C21 -> 55.871287 | F6: ='Financial Data Oracle'!D15/'Financial Data Oracle'!D21 -> 45.350299
A7: ORACLE | B7: Capital Structure | C7: Debt Ratio | D7: Total Debt / Total Assets | E7: ='Financial Data Oracle'!C8/'Financial Data Oracle'!C5 -> 0.87545215 | F7: ='Financial Data Oracle'!D8/'Financial Data Oracle'!D5 -> 0.93446402
A8: ORACLE | B8: Capital Structure | C8: Times Interest Earned | D8: Net Operational Income / Interest Expense | E8: ='Financial Data Oracle'!C18/'Financial Data Oracle'!C19 -> 18.075665 | F8: ='Financial Data Oracle'!D18/'Financial Data Oracle'!D19 -> 17.486333
A9: ORACLE | B9: Asset Management Efficiency Ratios | C9: Total Asset Turnover | D9: Sales / Total Assets | E9: ='Financial Data Oracle'!C12/'Financial Data Oracle'!C5 -> 0.34092812 | F9: ='Financial Data Oracle'!D12/'Financial Data Oracle'!D5 -> 0.37567387
A10: ORACLE | B10: Asset Management Efficiency Ratios | C10: Fixed Asset Turnover | D10: Sales / Net Plant and Equipment | E10: ='Financial Data Oracle'!C12/'Financial Data Oracle'!C14 -> 1.3188502 | F10: ='Financial Data Oracle'!D12/'Financial Data Oracle'!D14 -> 2.4591846
A11: ORACLE | B11: Profitability Ratios | C11: Gross Profit Margin | D11: Gross Profits / Sales | E11: ='Financial Data Oracle'!C16/'Financial Data Oracle'!C12 -> 0.70506455 | F11: ='Financial Data Oracle'!D16/'Financial Data Oracle'!D12 -> 0.71399709
A12: ORACLE | B12: Profitability Ratios | C12: Net Profit Margin | D12: Net Income / Sales | E12: ='Financial Data Oracle'!C20/'Financial Data Oracle'!C12 -> 0.21678078 | F12: ='Financial Data Oracle'!D20/'Financial Data Oracle'!D12 -> 0.197636
A13: ORACLE | B13: Profitability Ratios | C13: Operating Profit Margin | D13: Net Operating Income / Sales | E13: ='Financial Data Oracle'!C18/'Financial Data Oracle'!C12 -> 0.30798446 | F13: ='Financial Data Oracle'!D18/'Financial Data Oracle'!D12 -> 0.28989256
A14: ORACLE | B14: Profitability Ratios | C14: Operating Return on Assets | D14: Net Operating Income / Total Assets | E14: ='Financial Data Oracle'!C18/'Financial Data Oracle'!C5 -> 0.10500056 | F14: ='Financial Data Oracle'!D18/'Financial Data Oracle'!D5 -> 0.10890506
A15: ORACLE | B15: Profitability Ratios | C15: Return on Equity | D15: Net Income / Common Equity | E15: ='Financial Data Oracle'!C20/'Financial Data Oracle'!C9 -> 0.59339978 | F15: ='Financial Data Oracle'!D20/'Financial Data Oracle'!D9 -> 1.1329148
A16: ORACLE | B16: Market Value Ratios | C16: Price Earning Ratio | D16: Market Price per Share / Earnings per Share | E16: ='Financial Data Oracle'!C27/'Financial Data Oracle'!C30 -> 38.126576 | F16: ='Financial Data Oracle'!D27/'Financial Data Oracle'!D30 -> 37.707426
A17: ORACLE | B17: Market Value Ratios | C17: Market-to Book Ratio | D17: Market Price per Share / Book Value per Share | E17: ='Financial Data Oracle'!C27/'Financial Data Oracle'!C34 -> 22.624302 | F17: ='Financial Data Oracle'!D27/'Financial Data Oracle'!D34 -> 42.719302
A18: ORACLE | B18: DuPont Analysis | C18: Return on Equity (DuPont) | D18: Net Profit Margin * Total Asset Turnover * Equity Multiplier | E18: =E12*E9*E19 -> 0.59339978 | F18: =F12*F9*F19 -> 1.1329148
A19: ORACLE | B19: DuPont Analysis | C19: Equity Multiplier | D19: Total Assets / Common Equity | E19: ='Financial Data Oracle'!C5/'Financial Data Oracle'!C9 -> 8.0290429 | F19: ='Financial Data Oracle'!D5/'Financial Data Oracle'!D9 -> 15.258794

Sheet Financial Data Microsoft
A1: Company | B1: Item | C1: Result for 2025 | D1: Result for 2024 | E1: Remarks
A2: MICROSOFT | B2: Non Current Assets | C2: 427872 | D2: 352429
A3: MICROSOFT | B3: Current Assets | C3: 191131 | D3: 159734
A4: MICROSOFT | B4: Current Liablities | C4: 141218 | D4: 125286
A5: MICROSOFT | B5: Total Assets | C5: 619003 | D5: 512163
A6: MICROSOFT | B6: Non-Current Liablities | C6: 134306 | D6: 118400
A7: MICROSOFT | B7: Current Liabilities | C7: 141218 | D7: 125286
A8: MICROSOFT | B8: Total Liabilities | C8: 275524 | D8: 243686
A9: MICROSOFT | B9: Common Equity | C9: 109095 | D9: 100923
A10: MICROSOFT | B10: Total Equity | C10: 343479 | D10: 268477
A11: MICROSOFT | B11: Annual Credit Sales | C11: 281724 | D11: 245122 | E11: For Microsoft , “annual credit sales” are effectively its total annual revenue, because virtually all sales are on credit terms to customers rather than cash-on-the-spot transactions.
A12: MICROSOFT | B12: Revenue | C12: 281724 | D12: 245122
A13: MICROSOFT | B13: Total Operating Expenses | C13: 65365 | D13: 61575
A14: MICROSOFT | B14: Net Plant and Equipment | C14: 204966 | D14: 135593
A15: MICROSOFT | B15: Costs of Goods Sold or Costs of Revenue | C15: 87831 | D15: 74144
A16: MICROSOFT | B16: Gross Profit | C16: 193893 | D16: 171008
A17: MICROSOFT | B17: Operating Expenses | C17: 65365 | D17: 61575 | E17: Sum of R&D, Sales and Marketing and General and administrative
A18: MICROSOFT | B18: Net Operating Income | C18: 128528 | D18: 109433
A19: MICROSOFT | B19: Interest Expense | C19: 2425 | D19: 2983
A20: MICROSOFT | B20: Net Income | C20: 101832 | D20: 88136
A21: MICROSOFT | B21: Inventory | C21: 938 | D21: 1246
A22: MICROSOFT | B22: Accounts Receivable | C22: 69905 | D22: 56924
A23: MICROSOFT | B23: Shares Outstanding | C23: 7.434 | D23: 7.432
A24: MICROSOFT | B24: Shares Outstanding (Basic) | C24: 7.433 | D24: 7.31
A25: MICROSOFT | B25: Shares Outstanding (Diluted) | C25: 7.465 | D25: 7.469
A26: MICROSOFT | B26: Par Value per Share | C26: 6.25e-06 | D26: 6.25e-06
A27: MICROSOFT | B27: Market Price Per Share (as of June 30th) | C27: 496.59 | D27: 442.82
A28: MICROSOFT | B28: Market Price Per Share ( as of November 15th) | C28: 513.24 | D28: 422.92
A29: MICROSOFT | B29: Earnings per Share (Basic) | C29: 13.7 | D29: 11.86
A30: MICROSOFT | B30: Earnings per Share (Diluted) | C30: 13.64 | D30: 11.8
A31: MICROSOFT | B31: Market Cap. | C31: 3.7 trillion | D31: 3.3 trillion | E31: in trillions of dollars
A32: MICROSOFT | B32: Book Value per Share | C32: 46 | D32: 36
A33: MICROSOFT | B33: Book Value per Share (Basic) (Calculated) | C33: 46.18 | D33: 36.15
A34: MICROSOFT | B34: Book Value per Share (Diluted) (Calculated) | C34: 46 | D34: 35.94
A35: MICROSOFT | B35: Average Book Value | C35: =AVERAGE(C33:C34) -> 46.09 | D35: =AVERAGE(D33:D34) -> 36.045
B38: Figures Reading Guide
B39: 1. period functions as decimal separator, and comma as thousands
B40: 2. all of the figures are in millions
B41: 3. 2,3 means 2 billions of dollars where 2.3 basically means 2 point 3 dollars
B42: 4. exceptions are noted in the remarks column's cells
...

Sheet Financial Data Oracle
A1: Company | B1: Item | C1: Result for 2025 | D1: Result for 2024 | E1: remarks
A2: ORACLE | B2: Non Current Assets | C2: 143782 | D2: 118422
A3: ORACLE | B3: Current Assets | C3: 24579 | D3: 22554
A4: ORACLE | B4: Current Liablities | C4: 32554 | D4: 31554
A5: ORACLE | B5: Total Assets | C5: 168361 | D5: 140976
A6: ORACLE | B6: Non-Current Liablities | C6: 114749 | D6: 100193
A7: ORACLE | B7: Current Liabilities | C7: 32643 | D7: 31544
A8: ORACLE | B8: Total Liabilities | C8: =C6+C7 -> 147392 | D8: =D6+D7 -> 131737
A9: ORACLE | B9: Common Equity | C9: 20969 | D9: 9239
A10: ORACLE | B10: Total Equity | C10: 20969 | D10: 9239
A11: ORACLE | B11: Annual Credit Sales | C11: 49223 | D11: 44732 | E11: Comprises cloud services, license support, cloud license and on-premise license
A12: ORACLE | B12: Revenue | C12: 57399 | D12: 52961
A13: ORACLE | B13: Total Operating Expenses | C13: 39721 | D13: 37608
A14: ORACLE | B14: Net Plant and Equipment | C14: 43522 | D14: 21536
A15: ORACLE | B15: Costs of Goods Sold or Costs of Revenue | C15: 16929 | D15: 15147 | E15: https://www.macrotrends.net/stocks/charts/ORCL/oracle/gross-margin
A16: ORACLE | B16: Gross Profit | C16: =C12-C15 -> 40470 | D16: =D12-D15 -> 37814
A17: ORACLE | B17: Operating Expenses | C17: 22792 | D17: 22461
A18: ORACLE | B18: Net Operating Income | C18: =C16-C17 -> 17678 | D18: =D16-D17 -> 15353
A19: ORACLE | B19: Interest Expense | C19: 978 | D19: 878
A20: ORACLE | B20: Net Income | C20: 12443 | D20: 10467
A21: ORACLE | B21: Inventory | C21: 303 | D21: 334
A22: ORACLE | B22: Accounts Receivable | C22: 8558 | D22: 7874
A23: ORACLE | B23: Shares Outstanding | C23: 2807 | D23: 2755
A24: ORACLE | B24: Shares Outstanding (Basic) | C24: 2789 | D24: 2744
A25: ORACLE | B25: Shares Outstanding (Diluted) | C25: 2866 | D25: 2823
A26: ORACLE | B26: Par Value per Share | C26: 0.01 | D26: 0.01
A27: ORACLE | B27: Market Price Per Share ( as of May 31th) | C27: 165.53 | D27: 139.81
A28: ORACLE | B28: Market Price Per Share ( as of November 15th) | C28: 222.85 | D28: 115.01
A29: ORACLE | B29: Earnings per Share (Basic) | C29: =C20/C23 -> 4.4328465 | D29: =D20/D23 -> 3.799274
A30: ORACLE | B30: Earnings per Share (Diluted) | C30: =C20/C25 -> 4.3415911 | D30: =D20/D25 -> 3.7077577
A31: ORACLE | B31: Market Cap. | C31: 474,4 | D31: 394,7
A32: ORACLE | B32: Book Value per Share | C32: 13.01 | D32: 11.9
A33: ORACLE | B33: Book Value per Share (Basic) (Calculated) | C33: =C10/C24 -> 7.5184654 | D33: =D10/D24 -> 3.3669825
A34: ORACLE | B34: Book Value per Share (Diluted) (Calculated) | C34: =C10/C25 -> 7.3164689 | D34: =D10/D25 -> 3.2727595
A35: ORACLE | B35: Average Book Value | C35: =AVERAGE(C33:C34) -> 7.4174672 | D35: =AVERAGE(D33:D34) -> 3.319871
B38: Figures Reading Guide
B39: 1. period functions as decimal separator, and comma as thousands
B40: 2. all of the figures are in millions
B41: 3. 2,3 means 2 billions of dollars where 2.3 basically means 2 point 3 dollars
B42: 4. exceptions are noted in the remarks column's cells
...

Sheet Damodaran Benchmarks
A1: Index | B1: Type of Ratio | C1: Name | D1: Formula | E1: Result for 2025 | F1: Result for 2024 | G1: Remarks
A2: Dow Jones Tech | B2: Liquidy | C2: Current Ratio | D2: Current Assets / Current Liablities | E2: 1.88 | F2: 1.85 | G2: Links for the source: https://pages.stern.nyu.edu/~adamodar/
A3: Damodaran NYU | B3: Liquidy | C3: Quick Ratio (Acidity-Test) | D3: (Current Assets - Inventory) / Current Liabilities | E3: 1.65 | F3: 1.62
A4: Damodaran NYU | B4: Liquidity | C4: Average Collection Period | D4: 365 * Accounts Receivable / Annual Credit Sales | E4: 66 | F4: 68
A5: Damodaran NYU | B5: Liquidity | C5: Accounts Receivable Turnover | D5: Annual Credit Sales / Accounts Receivable | E5: 5.53 | F5: 5.37
A6: Damodaran NYU | B6: Liquidity | C6: Inventory Turnover | D6: Costs of Goods Sold / Inventory | E6: 13.2 | F6: 12.5
A7: Damodaran NYU | B7: Capital Structure | C7: Debt Ratio | D7: Total Debt / Total Assets | E7: 0.36 | F7: 0.38
A8: Damodaran NYU | B8: Capital Structure | C8: Times Interest Earned | D8: Net Operational Income / Interest Expense | E8: 24.1 | F8: 22.5
A9: Damodaran NYU | B9: Asset Management Efficiency Ratios | C9: Total Asset Turnover | D9: Sales / Total Assets | E9: 0.45 | F9: 0.42
A10: Damodaran NYU | B10: Asset Management Efficiency Ratios | C10: Fixed Asset Turnover | D10: Sales / Net Plant and Equipment | E10: 8.7 | F10: 8.2
A11: Damodaran NYU | B11: Profitability Ratios | C11: Gross Profit Margin | D11: Gross Profits / Sales | E11: 0.73 | F11: 0.72
A12: Damodaran NYU | B12: Profitability Ratios | C12: Net Profit Margin | D12: Net Income / Sales | E12: 0.26 | F12: 0.23
A13: Damodaran NYU | B13: Profitability Ratios | C13: Operating Profit Margin | D13: Net Operating Income / Sales | E13: 0.3 | F13: 0.29
A14: Damodaran NYU | B14: Profitability Ratios | C14: Operating Return on Assets | D14: Net Operating Income / Total Assets | E14: 0.135 | F14: 0.12
... A19: Damodaran NYU | B19: DuPont Analysis | C19: Equity Multiplier | D19: Total Assets / Common Equity | E19: 2.38 | F19: 2.45
